<?xml version="1.0" encoding="utf-8"?>
<!-- This URDF was automatically created by SolidWorks to URDF Exporter! Originally created by Stephen Brawner (brawner@gmail.com)
     Commit Version: 1.6.0-4-g7f85cfe  Build Version: 1.6.7995.38578
     For more information, please see http://wiki.ros.org/sw_urdf_exporter -->
<robot
  name="ehr_03">

  <mujoco>
		<compiler
		meshdir="../meshes"
		balanceinertia="true"
		discardvisual="false"/>
	</mujoco>

  <!-- <link name="world"></link> -->

	<!-- <joint name="floating_base_joint" type="floating">
		<parent link="world" />
		<child link="base_link" />
	</joint> -->

  <link name="base_link">
    <inertial>
      <origin
        xyz="-0.00044787 4.0773E-06 -0.0024229"
        rpy="0 0 0" />
      <mass
        value="6.2716" />
      <inertia
        ixx="0.010593"
        ixy="-2.1016E-07"
        ixz="2.0157E-06"
        iyy="0.018424"
        iyz="-5.3564E-09"
        izz="0.012768" />
    </inertial>
    <visual>
      <origin
        xyz="0 0 0"
        rpy="0 0 0" />
      <geometry>
        <mesh
          filename="../meshes/base_link.STL" />
      </geometry>
      <material
        name="">
        <color
          rgba="0.69804 0.69804 0.69804 1" />
      </material>
    </visual>
    <collision>
      <origin
        xyz="0 0 0.02"
        rpy="0 0 0" />
      <geometry>
        <box size="0.15 0.2 0.1"/>
      </geometry>
    </collision>
  </link>
    <link
    name="l_leg_l1">
    <inertial>
      <origin
        xyz="-0.04274 0.0696 -0.058751"
        rpy="0 0 0" />
      <mass
        value="2.3413" />
      <inertia
        ixx="0.0055647"
        ixy="-0.00015547"
        ixz="3.1596E-05"
        iyy="0.0056253"
        iyz="0.00056177"
        izz="0.0055552" />
    </inertial>
    <visual>
      <origin
        xyz="0 0 0"
        rpy="0 0 0" />
      <geometry>
        <mesh
          filename="../meshes/l_leg_l1.STL" />
      </geometry>
      <material
        name="">
        <color
          rgba="0.89804 0.92157 0.92941 1" />
      </material>
    </visual>
    <collision>
      <origin
        xyz="0 0.08 -0.07"
        rpy="0 0 0" />
      <geometry>
        <sphere radius="0.06"/>
      </geometry>
    </collision>
  </link>
  <joint
    name="l_leg_1"
    type="revolute">
    <origin
      xyz="0 0.10394 -0.022143"
      rpy="-0.43633 0 0" />
    <parent
      link="base_link" />
    <child
      link="l_leg_l1" />
    <axis
      xyz="0 1 0" />
    <limit
      lower="-1.57"
      upper="1.57"
      effort="320"
      velocity="14.137" />
  </joint>
  <link
    name="l_leg_l2">
    <inertial>
      <origin
        xyz="-0.00076602 4.848E-05 -0.054081"
        rpy="0 0 0" />
      <mass
        value="1.718" />
      <inertia
        ixx="0.0016615"
        ixy="-1.0431E-08"
        ixz="9.6968E-07"
        iyy="0.0017367"
        iyz="5.7052E-08"
        izz="0.0031832" />
    </inertial>
    <visual>
      <origin
        xyz="0 0 0"
        rpy="0 0 0" />
      <geometry>
        <mesh
          filename="../meshes/l_leg_l2.STL" />
      </geometry>
      <material
        name="">
        <color
          rgba="0.8902 0.8902 0.91373 1" />
      </material>
    </visual>

  </link>
  <joint
    name="l_leg_2"
    type="revolute">
    <origin
      xyz="0.01295 0.080175 -0.05872"
      rpy="0.42731 -0.21707 0" />
    <parent
      link="l_leg_l1" />
    <child
      link="l_leg_l2" />
    <axis
      xyz="1 0 0" />
    <limit
      lower="-0.2"
      upper="1.57"
      effort="150"
      velocity="14.661" />
  </joint>
  <link
    name="l_leg_l3">
    <inertial>
      <origin
        xyz="0.014982 0.0063694 -0.12969"
        rpy="0 0 0" />
      <mass
        value="4.3985" />
      <inertia
        ixx="0.017206"
        ixy="0.00087315"
        ixz="0.0024862"
        iyy="0.026754"
        iyz="-0.00018722"
        izz="0.012063" />
    </inertial>
    <visual>
      <origin
        xyz="0 0 0"
        rpy="0 0 0" />
      <geometry>
        <mesh
          filename="../meshes/l_leg_l3.STL" />
      </geometry>
      <material
        name="">
        <color
          rgba="0.75294 0.75294 0.75294 1" />
      </material>
    </visual>
    <collision>
      <origin
        xyz="0.025 0 -0.12"
        rpy="0 -0.15 -0.06" />
      <geometry>
        <box size="0.20 0.12 0.2"/>
      </geometry>
    </collision>
  </link>
  <joint
    name="l_leg_3"
    type="revolute">
    <origin
      xyz="0 0 -0.0865"
      rpy="0 0 0" />
    <parent
      link="l_leg_l2" />
    <child
      link="l_leg_l3" />
    <axis
      xyz="0 0 1" />
    <limit
      lower="-1.57"
      upper="1.57"
      effort="150"
      velocity="14.661" />
  </joint>
  <link
    name="l_leg_l4">
    <inertial>
      <origin
        xyz="-0.0088863 -8.3229E-06 -0.12174"
        rpy="0 0 0" />
      <mass
        value="2.2247" />
      <inertia
        ixx="0.01165"
        ixy="-8.6225E-06"
        ixz="-0.0043271"
        iyy="0.014401"
        iyz="-2.1865E-05"
        izz="0.0032245" />
    </inertial>
    <visual>
      <origin
        xyz="0 0 0"
        rpy="0 0 0" />
      <geometry>
        <mesh
          filename="../meshes/l_leg_l4.STL" />
      </geometry>
      <material
        name="">
        <color
          rgba="0.89804 0.92157 0.92941 1" />
      </material>
    </visual>
    <collision>
      <origin
        xyz="-0.025 0 -0.15"
        rpy="0 0.5 0" />
      <geometry>
        <box size="0.1 0.08 0.2"/>
      </geometry>
    </collision>
  </link>
  <joint
    name="l_leg_4"
    type="revolute">
    <origin
      xyz="0.015189 -0.0013882 -0.29433"
      rpy="0 0.19728 -0.091145" />
    <parent
      link="l_leg_l3" />
    <child
      link="l_leg_l4" />
    <axis
      xyz="0 1 0" />
    <limit
      lower="-0.523"
      upper="1.57"
      effort="320"
      velocity="14.137" />
  </joint>
  <link
    name="l_leg_l5">
    <inertial>
      <origin
        xyz="-1.1967E-07 -7.0818E-11 -8.5642E-08"
        rpy="0 0 0" />
      <mass
        value="0.078746" />
      <inertia
        ixx="1.0219E-05"
        ixy="-4.3227E-13"
        ixz="4.0927E-10"
        iyy="1.9028E-05"
        iyz="2.6232E-11"
        izz="1.7336E-05" />
    </inertial>
    <visual>
      <origin
        xyz="0 0 0"
        rpy="0 0 0" />
      <geometry>
        <mesh
          filename="../meshes/l_leg_l5.STL" />
      </geometry>
      <material
        name="">
        <color
          rgba="0.75294 0.75294 0.75294 1" />
      </material>
    </visual>

  </link>
  <joint
    name="l_leg_5"
    type="revolute">
    <origin
      xyz="-0.11555 0 -0.30947"
      rpy="0 0 0" />
    <parent
      link="l_leg_l4" />
    <child
      link="l_leg_l5" />
    <axis
      xyz="0 1 0" />
    <limit
      lower="-0.84"
      upper="0.7"
      effort="75"
      velocity="12.252" />
  </joint>
  <link
    name="l_leg_l6">
    <inertial>
      <origin
        xyz="-0.00819525144583517 -7.75010805531551E-10 -0.015608483675418"
        rpy="0 0 0" />
      <mass
        value="0.380900815380528" />
      <inertia
        ixx="0.000158341180452034"
        ixy="-8.95793500928833E-12"
        ixz="3.89608970374559E-06"
        iyy="0.000810570801972236"
        iyz="1.98256647510127E-11"
        izz="0.000944755476087221" />
    </inertial>
    <visual>
      <origin
        xyz="0 0 0"
        rpy="0 0 0" />
      <geometry>
        <mesh
          filename="../meshes/l_leg_l6.STL" />
      </geometry>
      <material
        name="">
        <color
          rgba="0.698039215686274 0.698039215686274 0.698039215686274 1" />
      </material>
    </visual>

  </link>
  <joint
    name="l_leg_6"
    type="revolute">
    <origin
      xyz="0 0 0"
      rpy="0 0 0" />
    <parent
      link="l_leg_l5" />
    <child
      link="l_leg_l6" />
    <axis
      xyz="1 0 0" />
    <limit
      lower="-0.45"
      upper="0.45"
      effort="75"
      velocity="12.252" />
  </joint>
  <link
    name="l_foot">
    <inertial>
      <origin
        xyz="0.0070568 2.74E-11 -0.0069279"
        rpy="0 0 0" />
      <mass
        value="0.20452" />
      <inertia
        ixx="0.00017384"
        ixy="2.7187E-12"
        ixz="2.7482E-06"
        iyy="0.0010753"
        iyz="3.2473E-14"
        izz="0.0012348" />
    </inertial>
    <visual>
      <origin
        xyz="0 0 0"
        rpy="0 0 0" />
      <geometry>
        <mesh
          filename="../meshes/l_foot.STL" />
      </geometry>
      <material
        name="">
        <color
          rgba="0.50196 0.50196 0.50196 1" />
      </material>
    </visual>
    <collision>
      <origin
        xyz="0 0 0"
        rpy="0 0 0" />
      <geometry>
        <mesh
          filename="../meshes/l_foot.STL" />
      </geometry>
    </collision>
  </link>
  <joint
    name="l_foot"
    type="fixed">
    <origin
      xyz="0 0 -0.0272500000000008"
      rpy="0 0 0" />
    <parent
      link="l_leg_l6" />
    <child
      link="l_foot" />
    <axis
      xyz="0 0 0" />
  </joint>

  <link
    name="r_leg_l1">
    <inertial>
      <origin
        xyz="-0.042746 -0.069664 -0.058722"
        rpy="0 0 0" />
      <mass
        value="2.3413" />
      <inertia
        ixx="0.0055647"
        ixy="0.00015572"
        ixz="3.1479E-05"
        iyy="0.0056253"
        iyz="-0.00056173"
        izz="0.0055551" />
    </inertial>
    <visual>
      <origin
        xyz="0 0 0"
        rpy="0 0 0" />
      <geometry>
        <mesh
          filename="../meshes/r_leg_l1.STL" />
      </geometry>
      <material
        name="">
        <color
          rgba="0.69804 0.69804 0.69804 1" />
      </material>
    </visual>
    <collision>
      <origin
        xyz="0 -0.08 -0.07"
        rpy="0 0 0" />
      <geometry>
        <sphere radius="0.06"/>
      </geometry>
    </collision>
  </link>
  <joint
    name="r_leg_1"
    type="revolute">
    <origin
      xyz="0 -0.10394 -0.022143"
      rpy="0.43633 0 0" />
    <parent
      link="base_link" />
    <child
      link="r_leg_l1" />
    <axis
      xyz="0 1 0" />
    <limit
      lower="-1.57"
      upper="1.57"
      effort="320"
      velocity="14.137" />
  </joint>
  <link
    name="r_leg_l2">
    <inertial>
      <origin
        xyz="-0.00077072 -5.3256E-05 -0.054096"
        rpy="0 0 0" />
      <mass
        value="1.7174" />
      <inertia
        ixx="0.0016615"
        ixy="-1.0515E-08"
        ixz="9.3275E-07"
        iyy="0.0017365"
        iyz="-1.3766E-07"
        izz="0.0031834" />
    </inertial>
    <visual>
      <origin
        xyz="0 0 0"
        rpy="0 0 0" />
      <geometry>
        <mesh
          filename="../meshes/r_leg_l2.STL" />
      </geometry>
      <material
        name="">
        <color
          rgba="0.89804 0.92157 0.92941 1" />
      </material>
    </visual>

  </link>
  <joint
    name="r_leg_2"
    type="revolute">
    <origin
      xyz="0.01295 -0.080175 -0.05872"
      rpy="-0.42731 -0.21707 0" />
    <parent
      link="r_leg_l1" />
    <child
      link="r_leg_l2" />
    <axis
      xyz="1 0 0" />
    <limit
      lower="-1.57"
      upper="0.2"
      effort="150"
      velocity="14.661" />
  </joint>
  <link
    name="r_leg_l3">
    <inertial>
      <origin
        xyz="0.015083 -0.0052987 -0.12857"
        rpy="0 0 0" />
      <mass
        value="4.4773" />
      <inertia
        ixx="0.017447"
        ixy="-0.00088928"
        ixz="0.0025286"
        iyy="0.027234"
        iyz="0.00018984"
        izz="0.012311" />
    </inertial>
    <visual>
      <origin
        xyz="0 0 0"
        rpy="0 0 0" />
      <geometry>
        <mesh
          filename="../meshes/r_leg_l3.STL" />
      </geometry>
      <material
        name="">
        <color
          rgba="0.79216 0.81961 0.93333 1" />
      </material>
    </visual>
    <collision>
      <origin
        xyz="0.025 0 -0.12"
        rpy="0 -0.15 0.06" />
      <geometry>
        <box size="0.20 0.12 0.2"/>
      </geometry>
    </collision>
  </link>
  <joint
    name="r_leg_3"
    type="revolute">
    <origin
      xyz="0 0 -0.0875"
      rpy="0 0 0" />
    <parent
      link="r_leg_l2" />
    <child
      link="r_leg_l3" />
    <axis
      xyz="0 0 1" />
    <limit
      lower="-1.57"
      upper="1.57"
      effort="150"
      velocity="14.661" />
  </joint>
  <link
    name="r_leg_l4">
    <inertial>
      <origin
        xyz="-0.0088864 7.0158E-06 -0.12174"
        rpy="0 0 0" />
      <mass
        value="2.2247" />
      <inertia
        ixx="0.011651"
        ixy="8.5688E-06"
        ixz="-0.0043275"
        iyy="0.014402"
        iyz="2.1733E-05"
        izz="0.0032246" />
    </inertial>
    <visual>
      <origin
        xyz="0 0 0"
        rpy="0 0 0" />
      <geometry>
        <mesh
          filename="../meshes/r_leg_l4.STL" />
      </geometry>
      <material
        name="">
        <color
          rgba="0.75686 0.76863 0.75294 1" />
      </material>
    </visual>
    <collision>
      <origin
        xyz="-0.025 0 -0.15"
        rpy="0 0.5 0" />
      <geometry>
        <box size="0.1 0.08 0.2"/>
      </geometry>
    </collision>
  </link>
  <joint
    name="r_leg_4"
    type="revolute">
    <origin
      xyz="0.015189 0.0013884 -0.29333"
      rpy="0 0.19728 0.091145" />
    <parent
      link="r_leg_l3" />
    <child
      link="r_leg_l4" />
    <axis
      xyz="0 1 0" />
    <limit
      lower="-0.523"
      upper="1.57"
      effort="320"
      velocity="14.137" />
  </joint>
  <link
    name="r_leg_l5">
    <inertial>
      <origin
        xyz="-1.2017E-07 5.0995E-09 -8.3322E-08"
        rpy="0 0 0" />
      <mass
        value="0.078746" />
      <inertia
        ixx="1.0219E-05"
        ixy="-4.7689E-13"
        ixz="3.7081E-10"
        iyy="1.9028E-05"
        iyz="2.6289E-11"
        izz="1.7336E-05" />
    </inertial>
    <visual>
      <origin
        xyz="0 0 0"
        rpy="0 0 0" />
      <geometry>
        <mesh
          filename="../meshes/r_leg_l5.STL" />
      </geometry>
      <material
        name="">
        <color
          rgba="0.75686 0.76863 0.75294 1" />
      </material>
    </visual>

  </link>
  <joint
    name="r_leg_5"
    type="revolute">
    <origin
      xyz="-0.11555 0 -0.30947"
      rpy="0 0 0" />
    <parent
      link="r_leg_l4" />
    <child
      link="r_leg_l5" />
    <axis
      xyz="0 1 0" />
    <limit
      lower="-0.84"
      upper="0.7"
      effort="75"
      velocity="12.252" />
  </joint>
  <link
    name="r_leg_l6">
    <inertial>
      <origin
        xyz="-0.00810563766236773 -1.90574214742334E-09 -0.015687039514419"
        rpy="0 0 0" />
      <mass
        value="0.379386899371904" />
      <inertia
        ixx="0.000158250047617737"
        ixy="-8.76844155971365E-12"
        ixz="3.89608813249665E-06"
        iyy="0.000810506032099252"
        iyz="2.21391622046152E-11"
        izz="0.000944710992210383" />
    </inertial>
    <visual>
      <origin
        xyz="0 0 0"
        rpy="0 0 0" />
      <geometry>
        <mesh
          filename="../meshes/r_leg_l6.STL" />
      </geometry>
      <material
        name="">
        <color
          rgba="0.698039215686274 0.698039215686274 0.698039215686274 1" />
      </material>
    </visual>

  </link>
  <joint
    name="r_leg_6"
    type="revolute">
    <origin
      xyz="0 0 0"
      rpy="0 0 0" />
    <parent
      link="r_leg_l5" />
    <child
      link="r_leg_l6" />
    <axis
      xyz="1 0 0" />
    <limit
      lower="-0.45"
      upper="0.45"
      effort="75"
      velocity="12.252" />
  </joint>
  <link
    name="r_foot">
    <inertial>
      <origin
        xyz="0.0070568 2.7395E-11 -0.0069279"
        rpy="0 0 0" />
      <mass
        value="0.20452" />
      <inertia
        ixx="0.00017384"
        ixy="2.7187E-12"
        ixz="2.7482E-06"
        iyy="0.0010753"
        iyz="3.2473E-14"
        izz="0.0012348" />
    </inertial>
    <visual>
      <origin
        xyz="0 0 0"
        rpy="0 0 0" />
      <geometry>
        <mesh
          filename="../meshes/r_foot.STL" />
      </geometry>
      <material
        name="">
        <color
          rgba="0.50196 0.50196 0.50196 1" />
      </material>
    </visual>
    <collision>
      <origin
        xyz="0 0 0"
        rpy="0 0 0" />
      <geometry>
        <mesh
          filename="../meshes/r_foot.STL" />
      </geometry>
    </collision>
  </link>
  <joint
    name="r_foot"
    type="fixed">
    <origin
      xyz="0 0 -0.027250001232115"
      rpy="0 0 0" />
    <parent
      link="r_leg_l6" />
    <child
      link="r_foot" />
    <axis
      xyz="0 0 0" />
  </joint>
  <link
    name="torso_l1">
    <inertial>
      <origin
        xyz="0.00032487 -0.0014995 0.075068"
        rpy="0 0 0" />
      <mass
        value="1.1107" />
      <inertia
        ixx="0.0012689"
        ixy="-1.1242E-07"
        ixz="3.7265E-06"
        iyy="0.002121"
        iyz="-1.397E-07"
        izz="0.00099899" />
    </inertial>
    <visual>
      <origin
        xyz="0 0 0"
        rpy="0 0 0" />
      <geometry>
        <mesh
          filename="../meshes/torso_l1.STL" />
      </geometry>
      <material
        name="">
        <color
          rgba="0.89804 0.92157 0.92941 1" />
      </material>
    </visual>

  </link>
  <joint
    name="torso_1"
    type="revolute">
    <origin
      xyz="0 0 0.076437"
      rpy="0 0 0" />
    <parent
      link="base_link" />
    <child
      link="torso_l1" />
    <axis
      xyz="0 0 1" />
    <limit
      lower="-2.1"
      upper="2.1"
      effort="60"
      velocity="15.603" />
  </joint>
  <link
    name="torso_l2">
    <inertial>
      <origin
        xyz="-0.023657 0.006306 0.0010904"
        rpy="0 0 0" />
      <mass
        value="0.33239" />
      <inertia
        ixx="0.00038273"
        ixy="1.0293E-05"
        ixz="-2.1754E-06"
        iyy="0.00040953"
        iyz="1.3248E-07"
        izz="0.00046519" />
    </inertial>
    <visual>
      <origin
        xyz="0 0 0"
        rpy="0 0 0" />
      <geometry>
        <mesh
          filename="../meshes/torso_l2.STL" />
      </geometry>
      <material
        name="">
        <color
          rgba="0.8902 0.8902 0.91373 1" />
      </material>
    </visual>
  </link>
  <joint
    name="torso_2"
    type="revolute">
    <origin
      xyz="0 0 0.081"
      rpy="0 0 0" />
    <parent
      link="torso_l1" />
    <child
      link="torso_l2" />
    <axis
      xyz="0 1 0" />
    <limit
      lower="-0.523"
      upper="0.523"
      effort="90"
      velocity="16.441" />
  </joint>
  <link
    name="torso_l3">
    <inertial>
      <origin
        xyz="0.031527 0.0015128 0.17859"
        rpy="0 0 0" />
      <mass
        value="11.139" />
      <inertia
        ixx="0.09006"
        ixy="-7.5054E-05"
        ixz="0.00033345"
        iyy="0.055413"
        iyz="0.0017487"
        izz="0.062453" />
    </inertial>
    <visual>
      <origin
        xyz="0 0 0"
        rpy="0 0 0" />
      <geometry>
        <mesh
          filename="../meshes/torso_l3.STL" />
      </geometry>
      <material
        name="">
        <color
          rgba="0.69804 0.69804 0.69804 1" />
      </material>
    </visual>
    <collision>
      <origin
        xyz="0.04 0 0.15"
        rpy="0 0 0" />
      <geometry>
        <box size="0.2 0.25 0.35"/>
      </geometry>
    </collision>
  </link>
  <joint
    name="torso_3"
    type="revolute">
    <origin
      xyz="-0.065 0 0"
      rpy="0 0 0" />
    <parent
      link="torso_l2" />
    <child
      link="torso_l3" />
    <axis
      xyz="1 0 0" />
    <limit
      lower="-0.523"
      upper="0.523"
      effort="60"
      velocity="15.603" />
  </joint>
  <link
    name="l_arm_l1">
    <inertial>
      <origin
        xyz="0.00388 0.075761 -0.0017659"
        rpy="0 0 0" />
      <mass
        value="0.85956" />
      <inertia
        ixx="0.0006078"
        ixy="-1.2012E-05"
        ixz="-5.8816E-05"
        iyy="0.00040682"
        iyz="5.8155E-06"
        izz="0.00051063" />
    </inertial>
    <visual>
      <origin
        xyz="0 0 0"
        rpy="0 0 0" />
      <geometry>
        <mesh
          filename="../meshes/l_arm_l1.STL" />
      </geometry>
      <material
        name="">
        <color
          rgba="0.75294 0.75294 0.75294 1" />
      </material>
    </visual>
    <collision>
      <origin
        xyz="0 -0.02 0"
        rpy="1.5708 0 0" />
      <geometry>
        <cylinder length="0.03" radius="0.05"/>
      </geometry>
    </collision>
  </link>
  <joint
    name="l_arm_1"
    type="revolute">
    <origin
      xyz="0.0335 0.1815 0.26"
      rpy="0 0 0" />
    <parent
      link="torso_l3" />
    <child
      link="l_arm_l1" />
    <axis
      xyz="0 1 0" />
    <limit
      lower="-3.58"
      upper="2.71"
      effort="60"
      velocity="15.603" />
  </joint>
  <link
    name="l_arm_l2">
    <inertial>
      <origin
        xyz="0.0013094 0.0064116 -0.063967"
        rpy="0 0 0" />
      <mass
        value="0.73729" />
      <inertia
        ixx="0.00099981"
        ixy="7.5582E-07"
        ixz="6.7801E-06"
        iyy="0.00082641"
        iyz="4.6711E-05"
        izz="0.00047693" />
    </inertial>
    <visual>
      <origin
        xyz="0 0 0"
        rpy="0 0 0" />
      <geometry>
        <mesh
          filename="../meshes/l_arm_l2.STL" />
      </geometry>
      <material
        name="">
        <color
          rgba="0.89804 0.91765 0.92941 1" />
      </material>
    </visual>
    <collision>
      <origin
        xyz="0 0 0"
        rpy="0 0 0" />
      <geometry>
        <sphere radius="0.055"/>
      </geometry>
    </collision>
  </link>
  <joint
    name="l_arm_2"
    type="revolute">
    <origin
      xyz="0 0.084 0"
      rpy="0 0.43633 0" />
    <parent
      link="l_arm_l1" />
    <child
      link="l_arm_l2" />
    <axis
      xyz="1 0 0" />
    <limit
      lower="-0.174"
      upper="2.966"
      effort="75"
      velocity="12.252" />
  </joint>
  <link
    name="l_arm_l3">
    <inertial>
      <origin
        xyz="0.0099976 -0.0059938 -0.071971"
        rpy="0 0 0" />
      <mass
        value="0.75417" />
      <inertia
        ixx="0.0006865"
        ixy="1.011E-05"
        ixz="5.1282E-05"
        iyy="0.00082922"
        iyz="-1.4371E-05"
        izz="0.00053733" />
    </inertial>
    <visual>
      <origin
        xyz="0 0 0"
        rpy="0 0 0" />
      <geometry>
        <mesh
          filename="../meshes/l_arm_l3.STL" />
      </geometry>
      <material
        name="">
        <color
          rgba="0.89804 0.91765 0.92941 1" />
      </material>
    </visual>
    <collision>
      <origin
        xyz="0 0 -0.022"
        rpy="0 0 0" />
      <geometry>
        <cylinder length="0.04" radius="0.045"/>
      </geometry>
    </collision>
  </link>
  <joint
    name="l_arm_3"
    type="revolute">
    <origin
      xyz="0 0.008 -0.112"
      rpy="0 0 0" />
    <parent
      link="l_arm_l2" />
    <child
      link="l_arm_l3" />
    <axis
      xyz="0 0 1" />
    <limit
      lower="-1.57"
      upper="1.57"
      effort="36"
      velocity="3" />
  </joint>
  <link
    name="l_arm_l4">
    <inertial>
      <origin
        xyz="-0.012236 -0.0010975 -0.068363"
        rpy="0 0 0" />
      <mass
        value="0.68148" />
      <inertia
        ixx="0.0006732"
        ixy="2.6217E-07"
        ixz="-4.1476E-05"
        iyy="0.00078309"
        iyz="-1.0113E-05"
        izz="0.00039393" />
    </inertial>
    <visual>
      <origin
        xyz="0 0 0"
        rpy="0 0 0" />
      <geometry>
        <mesh
          filename="../meshes/l_arm_l4.STL" />
      </geometry>
      <material
        name="">
        <color
          rgba="0.50196 0.50196 0.50196 1" />
      </material>
    </visual>
    <collision>
      <origin
        xyz="0 0 0"
        rpy="1.5708 0 0" />
      <geometry>
        <cylinder length="0.08" radius="0.045"/>
      </geometry>
    </collision>
  </link>
  <joint
    name="l_arm_4"
    type="revolute">
    <origin
      xyz="0.015 0 -0.0885"
      rpy="0 -0.7854 0" />
    <parent
      link="l_arm_l3" />
    <child
      link="l_arm_l4" />
    <axis
      xyz="0 1 0" />
    <limit
      lower="-1.74"
      upper="0.785"
      effort="36"
      velocity="9.320" />
  </joint>
  <link
    name="l_arm_l5">
    <inertial>
      <origin
        xyz="0.0025659 4.4452E-06 -0.046597"
        rpy="0 0 0" />
      <mass
        value="0.2475" />
      <inertia
        ixx="0.00033488"
        ixy="1.843E-08"
        ixz="4.7685E-06"
        iyy="0.00024661"
        iyz="6.3885E-07"
        izz="0.00014856" />
    </inertial>
    <visual>
      <origin
        xyz="0 0 0"
        rpy="0 0 0" />
      <geometry>
        <mesh
          filename="../meshes/l_arm_l5.STL" />
      </geometry>
      <material
        name="">
        <color
          rgba="0.50196 0.50196 0.50196 1" />
      </material>
    </visual>
    <collision>
      <origin
        xyz="0 0 0.01"
        rpy="0 0 0" />
      <geometry>
        <cylinder length="0.08" radius="0.045"/>
      </geometry>
    </collision>
  </link>
  <joint
    name="l_arm_5"
    type="revolute">
    <origin
      xyz="-0.015 0 -0.113"
      rpy="0 0 0" />
    <parent
      link="l_arm_l4" />
    <child
      link="l_arm_l5" />
    <axis
      xyz="0 0 1" />
    <limit
      lower="-0.37"
      upper="0.37"
      effort="36"
      velocity="9.320" />
  </joint>
  <link
    name="l_arm_l6">
    <inertial>
      <origin
        xyz="0.007913 0.0001143 -0.0018644"
        rpy="0 0 0" />
      <mass
        value="0.51802" />
      <inertia
        ixx="0.00036014"
        ixy="-1.8515E-07"
        ixz="-6.8734E-06"
        iyy="0.00024376"
        iyz="-7.9765E-07"
        izz="0.00021358" />
    </inertial>
    <visual>
      <origin
        xyz="0 0 0"
        rpy="0 0 0" />
      <geometry>
        <mesh
          filename="../meshes/l_arm_l6.STL" />
      </geometry>
      <material
        name="">
        <color
          rgba="0.69804 0.69804 0.69804 1" />
      </material>
    </visual>
    <collision>
      <origin
        xyz="0 0 0"
        rpy="0 1.5708 0" />
      <geometry>
        <cylinder length="0.08" radius="0.042"/>
      </geometry>
    </collision>
  </link>
  <joint
    name="l_arm_6"
    type="revolute">
    <origin
      xyz="0 0 -0.078965"
      rpy="0 0 0" />
    <parent
      link="l_arm_l5" />
    <child
      link="l_arm_l6" />
    <axis
      xyz="1 0 0" />
    <limit
      lower="-0.37"
      upper="0.385"
      effort="36"
      velocity="3" />
  </joint>
  <link
    name="l_hand">
    <inertial>
      <origin
        xyz="0.0023434 -0.001969 -0.090507"
        rpy="0 0 0" />
      <mass
        value="0.70576" />
      <inertia
        ixx="0.00030389"
        ixy="7.4364E-06"
        ixz="2.0531E-05"
        iyy="0.00045217"
        iyz="-7.6225E-06"
        izz="0.00031716" />
    </inertial>
    <visual>
      <origin
        xyz="0 0 0"
        rpy="0 0 0" />
      <geometry>
        <mesh
          filename="../meshes/l_hand.STL" />
      </geometry>
      <material
        name="">
        <color
          rgba="0.69804 0.69804 0.69804 1" />
      </material>
    </visual>
    <collision>
      <origin
        xyz="0 0 -0.1"
        rpy="0 0 0" />
      <geometry>
        <box size="0.1 0.1 0.2"/>
      </geometry>
    </collision>
  </link>
  <joint
    name="l_hand"
    type="fixed">
    <origin
      xyz="0 0 -0.0500000000000033"
      rpy="0 0 0" />
    <parent
      link="l_arm_l6" />
    <child
      link="l_hand" />
    <axis
      xyz="0 0 0" />
  </joint>
  <link
    name="r_arm_l1">
    <inertial>
      <origin
        xyz="0.0038783 -0.075768 -0.0017698"
        rpy="0 0 0" />
      <mass
        value="0.85955" />
      <inertia
        ixx="0.00060831"
        ixy="1.2702E-05"
        ixz="-5.7736E-05"
        iyy="0.00040401"
        iyz="-4.3459E-06"
        izz="0.00051294" />
    </inertial>
    <visual>
      <origin
        xyz="0 0 0"
        rpy="0 0 0" />
      <geometry>
        <mesh
          filename="../meshes/r_arm_l1.STL" />
      </geometry>
      <material
        name="">
        <color
          rgba="0.75294 0.75294 0.75294 1" />
      </material>
    </visual>
    <collision>
      <origin
        xyz="0 0.02 0"
        rpy="1.5708 0 0" />
      <geometry>
        <cylinder length="0.03" radius="0.05"/>
      </geometry>
    </collision>
  </link>
  <joint
    name="r_arm_1"
    type="revolute">
    <origin
      xyz="0.0335 -0.1815 0.26"
      rpy="0 0 0" />
    <parent
      link="torso_l3" />
    <child
      link="r_arm_l1" />
    <axis
      xyz="0 1 0" />
    <limit
      lower="-3.58"
      upper="2.71"
      effort="60"
      velocity="15.603" />
  </joint>
  <link
    name="r_arm_l2">
    <inertial>
      <origin
        xyz="-0.0001958 -0.0064125 -0.063954"
        rpy="0 0 0" />
      <mass
        value="0.73773" />
      <inertia
        ixx="0.00099983"
        ixy="-9.0241E-07"
        ixz="-1.6847E-05"
        iyy="0.00082642"
        iyz="-4.671E-05"
        izz="0.00047694" />
    </inertial>
    <visual>
      <origin
        xyz="0 0 0"
        rpy="0 0 0" />
      <geometry>
        <mesh
          filename="../meshes/r_arm_l2.STL" />
      </geometry>
      <material
        name="">
        <color
          rgba="0.79216 0.81961 0.93333 1" />
      </material>
    </visual>
    <collision>
      <origin
        xyz="0 0 0"
        rpy="0 0 0" />
      <geometry>
        <sphere radius="0.055"/>
      </geometry>
    </collision>
  </link>
  <joint
    name="r_arm_2"
    type="revolute">
    <origin
      xyz="0 -0.084 0"
      rpy="0 0.43633 0" />
    <parent
      link="r_arm_l1" />
    <child
      link="r_arm_l2" />
    <axis
      xyz="1 0 0" />
    <limit
      lower="-2.966"
      upper="0.174"
      effort="75"
      velocity="12.252" />
  </joint>
  <link
    name="r_arm_l3">
    <inertial>
      <origin
        xyz="0.0099973 0.0059927 -0.073434"
        rpy="0 0 0" />
      <mass
        value="0.7541" />
      <inertia
        ixx="0.00068645"
        ixy="-1.0111E-05"
        ixz="5.1466E-05"
        iyy="0.00082922"
        iyz="3.8003E-05"
        izz="0.00053737" />
    </inertial>
    <visual>
      <origin
        xyz="0 0 0"
        rpy="0 0 0" />
      <geometry>
        <mesh
          filename="../meshes/r_arm_l3.STL" />
      </geometry>
      <material
        name="">
        <color
          rgba="0.79216 0.81961 0.93333 1" />
      </material>
    </visual>
    <collision>
      <origin
        xyz="0 0 -0.022"
        rpy="0 0 0" />
      <geometry>
        <cylinder length="0.04" radius="0.045"/>
      </geometry>
    </collision>
  </link>
  <joint
    name="r_arm_3"
    type="revolute">
    <origin
      xyz="0 -0.008 -0.112"
      rpy="0 0 0" />
    <parent
      link="r_arm_l2" />
    <child
      link="r_arm_l3" />
    <axis
      xyz="0 0 1" />
    <limit
      lower="-1.57"
      upper="1.57"
      effort="36"
      velocity="3" />
  </joint>
  <link
    name="r_arm_l4">
    <inertial>
      <origin
        xyz="0.039684 0.0010979 -0.056997"
        rpy="0 0 0" />
      <mass
        value="0.68148" />
      <inertia
        ixx="0.00057511"
        ixy="-7.231E-06"
        ixz="0.00013963"
        iyy="0.00078309"
        iyz="7.0543E-06"
        izz="0.00049202" />
    </inertial>
    <visual>
      <origin
        xyz="0 0 0"
        rpy="0 0 0" />
      <geometry>
        <mesh
          filename="../meshes/r_arm_l4.STL" />
      </geometry>
      <material
        name="">
        <color
          rgba="0.29804 0.29804 0.29804 1" />
      </material>
    </visual>
    <collision>
      <origin
        xyz="0 0 0"
        rpy="1.5708 0 0" />
      <geometry>
        <cylinder length="0.08" radius="0.045"/>
      </geometry>
    </collision>
  </link>
  <joint
    name="r_arm_4"
    type="revolute">
    <origin
      xyz="0.015 0 -0.0885"
      rpy="0 0 0" />
    <parent
      link="r_arm_l3" />
    <child
      link="r_arm_l4" />
    <axis
      xyz="0 1 0" />
    <limit
      lower="-1.74"
      upper="0.785"
      effort="36"
      velocity="9.320" />
  </joint>
  <link
    name="r_arm_l5">
    <inertial>
      <origin
        xyz="0.004319 -5.2542E-06 -0.044878"
        rpy="0 0 0" />
      <mass
        value="0.2372" />
      <inertia
        ixx="0.00032966"
        ixy="-1.8563E-08"
        ixz="4.7694E-06"
        iyy="0.000244"
        iyz="-6.3752E-07"
        izz="0.00014594" />
    </inertial>
    <visual>
      <origin
        xyz="0 0 0"
        rpy="0 0 0" />
      <geometry>
        <mesh
          filename="../meshes/r_arm_l5.STL" />
      </geometry>
      <material
        name="">
        <color
          rgba="0.79216 0.81961 0.93333 1" />
      </material>
    </visual>
    <collision>
      <origin
        xyz="0 0 0.01"
        rpy="0 0 0" />
      <geometry>
        <cylinder length="0.08" radius="0.045"/>
      </geometry>
    </collision>
  </link>
  <joint
    name="r_arm_5"
    type="revolute">
    <origin
      xyz="0.069296 0 -0.09051"
      rpy="0 -0.7854 0" />
    <parent
      link="r_arm_l4" />
    <child
      link="r_arm_l5" />
    <axis
      xyz="0 0 1" />
    <limit
      lower="-0.37"
      upper="0.37"
      effort="36"
      velocity="9.320" />
  </joint>
  <link
    name="r_arm_l6">
    <inertial>
      <origin
        xyz="0.007913 -0.00011464 -0.0022677"
        rpy="0 0 0" />
      <mass
        value="0.51802" />
      <inertia
        ixx="0.00036015"
        ixy="1.828E-07"
        ixz="-5.9816E-06"
        iyy="0.00024376"
        iyz="7.4711E-07"
        izz="0.00021358" />
    </inertial>
    <visual>
      <origin
        xyz="0 0 0"
        rpy="0 0 0" />
      <geometry>
        <mesh
          filename="../meshes/r_arm_l6.STL" />
      </geometry>
      <material
        name="">
        <color
          rgba="0.69804 0.69804 0.69804 1" />
      </material>
    </visual>
    <collision>
      <origin
        xyz="0 0 0"
        rpy="0 1.5708 0" />
      <geometry>
        <cylinder length="0.08" radius="0.042"/>
      </geometry>
    </collision>
  </link>
  <joint
    name="r_arm_6"
    type="revolute">
    <origin
      xyz="0 0 -0.078465"
      rpy="0 0 0" />
    <parent
      link="r_arm_l5" />
    <child
      link="r_arm_l6" />
    <axis
      xyz="1 0 0" />
    <limit
      lower="-0.385"
      upper="0.37"
      effort="36"
      velocity="3" />
  </joint>
  <link
    name="r_hand">
    <inertial>
      <origin
        xyz="0.002153 0.0022194 -0.091965"
        rpy="0 0 0" />
      <mass
        value="0.70318" />
      <inertia
        ixx="0.00070478"
        ixy="-1.0092E-05"
        ixz="1.4584E-05"
        iyy="0.00084179"
        iyz="-3.932E-06"
        izz="0.00031339" />
    </inertial>
    <visual>
      <origin
        xyz="0 0 0"
        rpy="0 0 0" />
      <geometry>
        <mesh
          filename="../meshes/r_hand.STL" />
      </geometry>
      <material
        name="">
        <color
          rgba="0.69804 0.69804 0.69804 1" />
      </material>
    </visual>
    <collision>
      <origin
        xyz="0 0 -0.1"
        rpy="0 0 0" />
      <geometry>
        <box size="0.1 0.1 0.2"/>
      </geometry>
    </collision>
  </link>
  <joint
    name="r_hand"
    type="fixed">
    <origin
      xyz="0 0.000347030541417714 -0.050000000000004"
      rpy="0 0 0" />
    <parent
      link="r_arm_l6" />
    <child
      link="r_hand" />
    <axis
      xyz="0 0 0" />
  </joint>

</robot>